{"uuid": "5216179d-e1a9-4ef1-84d7-89a541c05c0b", "children": ["13e46715-423e-4b37-983f-a31d3ea6721d"], "befores": [{"name": "browser", "status": "broken", "statusDetails": {"message": "urllib3.exceptions.MaxRetryError: HTTPConnectionPool(host='192.168.8.131', port=4444): Max retries exceeded with url: /wd/hub/session (Caused by NewConnectionError('<urllib3.connection.HTTPConnection object at 0x7f4d6a538470>: Failed to establish a new connection: [Errno 111] Connection refused',))\n", "trace": "  File \"/home/max/.local/lib/python3.6/site-packages/pluggy/_callers.py\", line 39, in _multicall\n    res = hook_impl.function(*args)\n  File \"/home/max/.local/lib/python3.6/site-packages/_pytest/fixtures.py\", line 1126, in pytest_fixture_setup\n    result = call_fixture_func(fixturefunc, request, kwargs)\n  File \"/home/max/.local/lib/python3.6/site-packages/_pytest/fixtures.py\", line 932, in call_fixture_func\n    fixture_result = fixturefunc(**kwargs)\n  File \"/home/max/logging_in_PO/conftest.py\", line 59, in browser\n    desired_capabilities=caps\n  File \"/home/max/.local/lib/python3.6/site-packages/selenium/webdriver/remote/webdriver.py\", line 157, in __init__\n    self.start_session(capabilities, browser_profile)\n  File \"/home/max/.local/lib/python3.6/site-packages/selenium/webdriver/remote/webdriver.py\", line 252, in start_session\n    response = self.execute(Command.NEW_SESSION, parameters)\n  File \"/home/max/.local/lib/python3.6/site-packages/selenium/webdriver/remote/webdriver.py\", line 319, in execute\n    response = self.command_executor.execute(driver_command, params)\n  File \"/home/max/.local/lib/python3.6/site-packages/selenium/webdriver/remote/remote_connection.py\", line 374, in execute\n    return self._request(command_info[0], url, body=data)\n  File \"/home/max/.local/lib/python3.6/site-packages/selenium/webdriver/remote/remote_connection.py\", line 402, in _request\n    resp = http.request(method, url, body=body, headers=headers)\n  File \"/usr/lib/python3/dist-packages/urllib3/request.py\", line 70, in request\n    **urlopen_kw)\n  File \"/usr/lib/python3/dist-packages/urllib3/request.py\", line 148, in request_encode_body\n    return self.urlopen(method, url, **extra_kw)\n  File \"/usr/lib/python3/dist-packages/urllib3/poolmanager.py\", line 322, in urlopen\n    response = conn.urlopen(method, u.request_uri, **kw)\n  File \"/usr/lib/python3/dist-packages/urllib3/connectionpool.py\", line 668, in urlopen\n    **response_kw)\n  File \"/usr/lib/python3/dist-packages/urllib3/connectionpool.py\", line 668, in urlopen\n    **response_kw)\n  File \"/usr/lib/python3/dist-packages/urllib3/connectionpool.py\", line 668, in urlopen\n    **response_kw)\n  File \"/usr/lib/python3/dist-packages/urllib3/connectionpool.py\", line 639, in urlopen\n    _stacktrace=sys.exc_info()[2])\n  File \"/usr/lib/python3/dist-packages/urllib3/util/retry.py\", line 398, in increment\n    raise MaxRetryError(_pool, url, error or ResponseError(cause))\n"}, "start": 1632393444495, "stop": 1632393453577}], "start": 1632393444495, "stop": 1632393454587}