{"uuid": "08555162-3291-4d2f-ad46-477822d7d059", "children": ["7fe4f012-bb2f-4867-bd56-0e98e01c036c"], "befores": [{"name": "browser", "status": "broken", "statusDetails": {"message": "urllib3.exceptions.MaxRetryError: HTTPConnectionPool(host='192.168.8.131', port=4444): Max retries exceeded with url: /wd/hub/session (Caused by NewConnectionError('<urllib3.connection.HTTPConnection object at 0x7f8d015032b0>: Failed to establish a new connection: [Errno 111] Connection refused',))\n", "trace": "  File \"/home/max/venv/lib/python3.6/site-packages/pluggy/callers.py\", line 187, in _multicall\n    res = hook_impl.function(*args)\n  File \"/home/max/venv/lib/python3.6/site-packages/_pytest/fixtures.py\", line 1126, in pytest_fixture_setup\n    result = call_fixture_func(fixturefunc, request, kwargs)\n  File \"/home/max/venv/lib/python3.6/site-packages/_pytest/fixtures.py\", line 932, in call_fixture_func\n    fixture_result = fixturefunc(**kwargs)\n  File \"/home/max/logging_in_PO/conftest.py\", line 59, in browser\n    desired_capabilities=caps\n  File \"/home/max/venv/lib/python3.6/site-packages/selenium/webdriver/remote/webdriver.py\", line 157, in __init__\n    self.start_session(capabilities, browser_profile)\n  File \"/home/max/venv/lib/python3.6/site-packages/selenium/webdriver/remote/webdriver.py\", line 252, in start_session\n    response = self.execute(Command.NEW_SESSION, parameters)\n  File \"/home/max/venv/lib/python3.6/site-packages/selenium/webdriver/remote/webdriver.py\", line 319, in execute\n    response = self.command_executor.execute(driver_command, params)\n  File \"/home/max/venv/lib/python3.6/site-packages/selenium/webdriver/remote/remote_connection.py\", line 374, in execute\n    return self._request(command_info[0], url, body=data)\n  File \"/home/max/venv/lib/python3.6/site-packages/selenium/webdriver/remote/remote_connection.py\", line 402, in _request\n    resp = http.request(method, url, body=body, headers=headers)\n  File \"/home/max/venv/lib/python3.6/site-packages/urllib3/request.py\", line 79, in request\n    method, url, fields=fields, headers=headers, **urlopen_kw\n  File \"/home/max/venv/lib/python3.6/site-packages/urllib3/request.py\", line 170, in request_encode_body\n    return self.urlopen(method, url, **extra_kw)\n  File \"/home/max/venv/lib/python3.6/site-packages/urllib3/poolmanager.py\", line 375, in urlopen\n    response = conn.urlopen(method, u.request_uri, **kw)\n  File \"/home/max/venv/lib/python3.6/site-packages/urllib3/connectionpool.py\", line 796, in urlopen\n    **response_kw\n  File \"/home/max/venv/lib/python3.6/site-packages/urllib3/connectionpool.py\", line 796, in urlopen\n    **response_kw\n  File \"/home/max/venv/lib/python3.6/site-packages/urllib3/connectionpool.py\", line 796, in urlopen\n    **response_kw\n  File \"/home/max/venv/lib/python3.6/site-packages/urllib3/connectionpool.py\", line 756, in urlopen\n    method, url, error=e, _pool=self, _stacktrace=sys.exc_info()[2]\n  File \"/home/max/venv/lib/python3.6/site-packages/urllib3/util/retry.py\", line 574, in increment\n    raise MaxRetryError(_pool, url, error or ResponseError(cause))\n"}, "start": 1632393592772, "stop": 1632393601845}], "start": 1632393592772, "stop": 1632393602182}